{
  "comments": [
    {
      "unresolved": false,
      "key": {
        "uuid": "d1ed2a2b_37e5b050",
        "filename": "/PATCHSET_LEVEL",
        "patchSetId": 13
      },
      "lineNbr": 0,
      "author": {
        "id": 1000593
      },
      "writtenOn": "2022-04-07T21:22:43Z",
      "side": 1,
      "message": "Thanks for looking this over",
      "revId": "76938008992cae3312bb5c3061005382970a0de6",
      "serverId": "adbd0a64-1f21-4d83-b585-671fe73cb6e4"
    },
    {
      "unresolved": true,
      "key": {
        "uuid": "2aa3b61a_73573163",
        "filename": "src/test/erase/pattern_test.cpp",
        "patchSetId": 13
      },
      "lineNbr": 219,
      "author": {
        "id": 1001202
      },
      "writtenOn": "2022-04-08T23:16:39Z",
      "side": 1,
      "message": "I think it\u0027d be better if you remove this line, and let your test call write() one more time, with the same behavior as before. This will make sure that your code throws an exception when the max retries is reached. Instead, you\u0027re having the write function throw the exception without testing your max retries logic.",
      "range": {
        "startLine": 219,
        "startChar": 4,
        "endLine": 219,
        "endChar": 60
      },
      "revId": "76938008992cae3312bb5c3061005382970a0de6",
      "serverId": "adbd0a64-1f21-4d83-b585-671fe73cb6e4"
    }
  ]
}